Workbook

Sheet Leia-me
A1: Recife Resiliente — Critérios para hierarquizar pontos críticos de alagamento (RPA 6)
A2: Rascunho de 01/10/2026 (Pedro + Claude). Não validado pelo grupo.
A3: HISTÓRICO | B3: Arquivo histórico (rascunho de 01/10/2026), substituído em 03/10/2026. O modelo atual tem 4 dimensões (Probabilidade, Exposição, Vulnerabilidade, Impacto) e 19 variáveis. Trabalhar na planilha Google 'Recife_Resiliente_Checklist_Variaveis' (abas Checklist variáveis e Notas dos pontos) e no documento-chave docs/10-dimensoes-e-variaveis.md. Não atualizar este arquivo.
A4: O que é | B4: Estrutura de critérios e subcritérios adaptada do Plano de Ações do Plano Diretor de Drenagem de São Paulo (que hierarquiza obras) para hierarquizar PONTOS críticos de alagamento. Escopo: apenas RPA 6.
A5: Abas | B5: Critérios: dimensões, subcritérios, como medir, escala 1–5, fonte, quem fornece, status do dado e peso. | Fontes de dados: inventário das fontes, com link, como obter e status. | Pontos RPA 6: tabela para pontuar cada ponto e calcular o score.
A6: Escala | B6: Cada subcritério recebe nota de 1 a 5, onde 5 = contribui MAIS para a criticidade. Nos itens inversos (infraestrutura verde, acessibilidade de resposta) a escala já vem invertida. Na tratabilidade, 5 = mais fácil de intervir.
A7: [SIG] e [Ponto] | B7: [SIG] = calculado no círculo de 300 m em torno do ponto (ArcGIS Pro, projeção SIRGAS 2000 / UTM 25S, EPSG:31985). [Ponto] = atributo do próprio ponto, obtido de órgãos, vistoria ou campo.
A8: Faixas | B8: As faixas absolutas são PROVISÓRIAS: calibrar com os dados reais. Onde não há referência, usa-se quintis dos pontos da RPA 6 (nota relativa ao conjunto, não absoluta).
A9: Sem dado | B9: Sem dado acessível, o subcritério sai e os pesos dos demais são redistribuídos (a fórmula da aba Pontos RPA 6 já ignora notas em branco). Registrar a ausência.
A10: Pesos | B10: Ainda não definidos. Método de SP: cada membro do grupo propõe pesos separadamente, depois discutem. Preencher a coluna Peso na aba Critérios (células amarelas); a soma deve dar 100%.
A11: Cores | B11: Texto azul em fundo amarelo = célula para preencher. Texto azul claro sublinhado = link. Fundo cinza = não se aplica ao score.
A12: Cuidados | B12: Os links marcados como 'Confirmado na busca' existem, mas o conteúdo de cada base não foi aberto na íntegra. Fontes marcadas 'Não verificado' (CNES, OpenStreetMap, MapBiomas, tábua de marés, dados de ônibus) foram citadas por conhecimento geral e precisam ser conferidas. A existência de dados por ponto (frequência, altura da lâmina, custos) depende de COP, Defesa Civil, EMLURB e Compesa.
A13: Referência | B13: Plano Diretor de Drenagem de São Paulo (FCTH/SIURB), Plano de Ações, cap. 5 e Tabelas 3–6: https://drive.prefeitura.sp.gov.br/cidade/secretarias/upload/obras/cadernos_de_drenagem/FCTH_PDD.pdf

Sheet Critérios
A1: Critérios e subcritérios — como medir e onde obter os dados
A2: Nota 5 = mais crítico (itens inversos já invertidos). Faixas provisórias. Células amarelas: preencher (Status do dado e Peso).
A4: Nº | B4: Dimensão | C4: Subcritério | D4: Tipo | E4: Efeito no score | F4: Pergunta que responde | G4: Como medir | H4: Nota 1 | I4: Nota 2 | J4: Nota 3 | K4: Nota 4 | L4: Nota 5 | M4: Fonte principal do dado | N4: Link | O4: Quem fornece / onde pedir | P4: Observações | Q4: Status do dado | R4: Peso
A5: 1 | B5: 1. Hidrológico | C5: Frequência de eventos | D5: Ponto | E5: Aumenta | F5: Quantas vezes o ponto alaga por ano? | G5: Média de eventos/ano nas 3 últimas estações chuvosas (evento = ocorrência registrada). | H5: <1 | I5: 1–2 | J5: 3–4 | K5: 5–6 | L5: ≥7 | M5: Registro de ocorrências do COP e da Defesa Civil (Sedec); 156 como complemento. | O5: COP; Defesa Civil (Sedec) | P5: Faixas provisórias: calibrar com a distribuição real dos pontos da RPA 6. | Q5: A verificar
A6: 2 | B6: 1. Hidrológico | C6: Gatilho de chuva | D6: Ponto | E6: Aumenta (quanto menor o gatilho) | F6: Com que chuva o ponto alaga? | G6: Menor chuva (mm/24h) que já causou alagamento: cruzar a data da ocorrência com o pluviômetro mais próximo. | H6: >80 mm | I6: 60–80 mm | J6: 40–60 mm | K6: 20–40 mm | L6: <20 mm | M6: Pluviômetros Cemaden (download por equipamento, mês a mês, desde 2013) e APAC. | N6: Abrir | O6: Cemaden; APAC; Defesa Civil | P6: Depende de ter datas confiáveis das ocorrências (critério anterior). Faixas provisórias. | Q6: A verificar
A7: 3 | B7: 1. Hidrológico | C7: Influência da maré | D7: Ponto | E7: Aumenta | F7: A maré ou o nível do rio bloqueia o escoamento? | G7: Classificação qualitativa por escuta e dados de maré. | H7: Não influencia | I7: — | J7: Agrava ocasionalmente | K7: — | L7: Alaga dependendo da maré / escoamento bloqueado | M7: APAC e tábua de marés; escuta de campo. | N7: Abrir | O7: APAC; Marinha (tábua de marés, a verificar); campo | P7: Relevante nas áreas de baixada da RPA 6. | Q7: A verificar
A8: 4 | B8: 1. Hidrológico | C8: Altura da lâmina d'água | D8: Ponto | E8: Aumenta | F8: Quão alta fica a água? | G8: Maior altura registrada ou relatada. Registrar em faixas de campo (tornozelo, joelho, cintura). | H8: <10 cm | I8: 10–30 cm | J8: 30–50 cm | K8: 50–100 cm | L8: >100 cm | M8: Campo e escuta de moradores e equipes; modelagem se houver. | O8: Campo; Defesa Civil; EMLURB | P8: Dado raramente sistemático. SP incluiu 'altura da mancha' na 3ª edição. | Q8: A verificar
A9: 5 | B9: 1. Hidrológico | C9: Extensão da mancha | D9: Ponto | E9: Aumenta | F9: Qual a área ou o comprimento alagado? | G9: Comprimento de via ou área alagada (m ou m²). | H9: Quintil 1 (20% menores) | I9: Quintil 2 | J9: Quintil 3 | K9: Quintil 4 | L9: Quintil 5 (20% maiores) | M9: Campo, topografia ou modelagem; áreas inundáveis, se existirem em camada da Prefeitura. | O9: Campo; EMLURB; URB | P9: Quintis calculados sobre os pontos da RPA 6. | Q9: A verificar
A10: 6 | B10: 1. Hidrológico | C10: Duração do alagamento | D10: Ponto | E10: Aumenta | F10: Quanto tempo leva para a água baixar? | G10: Horas até a água baixar após a chuva. | H10: <1 h | I10: 1–3 h | J10: 3–6 h | K10: 6–12 h | L10: >12 h | M10: Campo e escuta de moradores. | O10: Campo; Defesa Civil | P10: Faixas provisórias. | Q10: A verificar
A11: 7 | B11: 2. Social | C11: População exposta | D11: SIG | E11: Aumenta | F11: Quantas pessoas vivem no entorno do ponto? | G11: Habitantes no círculo de 300 m: soma de (população do setor × proporção da área do setor dentro do círculo). | H11: Quintil 1 (20% menores) | I11: Quintil 2 | J11: Quintil 3 | K11: Quintil 4 | L11: Quintil 5 (20% maiores) | M11: IBGE, Censo 2022: agregados por setor censitário + malha de setores. | N11: Abrir | O11: IBGE (download público) | P11: Estimativa: assume população uniforme dentro do setor. Registrar como estimativa. | Q11: A verificar
A12: 8 | B12: 2. Social | C12: Vulnerabilidade social | D12: SIG | E12: Aumenta | F12: Quem mora ali é mais vulnerável? | G12: Maior IVS entre as UDH que intersectam o círculo (análogo ao IPVS usado por SP). | H12: Muito baixa | I12: Baixa | J12: Média | K12: Alta | L12: Muito alta | M12: Ipea: Índice de Vulnerabilidade Social por UDH. | N12: Abrir | O12: Ipea (público) | P12: Dados de 2000 e 2010; granularidade UDH. Conferir cortes das faixas do IVS. Provisório até haver índice local mais recente. | Q12: A verificar
A13: 9 | B13: 2. Social | C13: Grupos sensíveis | D13: SIG | E13: Aumenta | F13: Há muitos idosos e crianças pequenas? | G13: % de moradores idosos e crianças pequenas nos setores do círculo. | H13: Quintil 1 (20% menores) | I13: Quintil 2 | J13: Quintil 3 | K13: Quintil 4 | L13: Quintil 5 (20% maiores) | M13: IBGE, Censo 2022 (se o agregado por setor trouxer faixa etária); cadastros locais. | N13: Abrir | O13: IBGE; Assistência Social/saúde (cadastros) | P13: Confirmar se a faixa etária está disponível por setor. | Q13: A verificar
A14: 10 | B14: 3. Econômico | C14: Comércios no entorno | D14: SIG | E14: Aumenta | F14: Quanto comércio fica exposto? | G14: Nº de estabelecimentos comerciais no círculo de 300 m. | H14: Quintil 1 (20% menores) | I14: Quintil 2 | J14: Quintil 3 | K14: Quintil 4 | L14: Quintil 5 (20% maiores) | M14: Dados abertos da Prefeitura (empresas/alvarás, a verificar) ou OpenStreetMap. | N14: Abrir | O14: Prefeitura do Recife (dados abertos) | P14: Verificar no portal se há conjunto georreferenciado de estabelecimentos. | Q14: A verificar
A15: 11 | B15: 3. Econômico | C15: Importância das edificações | D15: SIG | E15: Aumenta | F15: Que tipo de uso está exposto? | G15: Classe mais crítica presente no círculo (escala adaptada de SP). | H15: Espaço público | I15: — | J15: Comercial | K15: Residencial | L15: Equipamento vulnerável (escola, creche, unidade de saúde) | M15: Uso do solo/edificações da Prefeitura; equipamentos públicos. | N15: Abrir | O15: Prefeitura do Recife | P15: Escala de SP: equipamento vulnerável 5, residencial 4, comercial 3, espaço público 1. | Q15: A verificar
A16: 12 | B16: 3. Econômico | C16: Custo recorrente de conviver com o ponto | D16: Ponto | E16: Aumenta | F16: Quanto a Prefeitura gasta repetidamente com o ponto? | G16: R$/ano ou nº de acionamentos/ano de equipes de limpeza e resposta no ponto. | H16: Quintil 1 (20% menores) | I16: Quintil 2 | J16: Quintil 3 | K16: Quintil 4 | L16: Quintil 5 (20% maiores) | M16: Registros de serviço da EMLURB e da Defesa Civil. | O16: EMLURB; Defesa Civil | P16: Pode não existir por ponto: se não houver dado, o subcritério sai (regra de corte). | Q16: A verificar
A17: 13 | B17: 4. Infraestrutura urbana e mobilidade | C17: Vias e mobilidade afetadas | D17: SIG | E17: Aumenta | F17: Quanto da mobilidade é cortada? | G17: Km de via no círculo ponderado pela classe viária e/ou nº de linhas de ônibus que usam a via alagada (versão local de 'viagens impactadas', 3ª ed. de SP). | H17: Quintil 1 (20% menores) | I17: Quintil 2 | J17: Quintil 3 | K17: Quintil 4 | L17: Quintil 5 (20% maiores) | M17: Malha viária da Prefeitura/OSM; dados de linhas de ônibus (CTTU/Grande Recife, a verificar). | N17: Abrir | O17: Prefeitura (CTTU); Grande Recife Consórcio | P17: Dados de transporte não verificados. | Q17: A verificar
A18: 14 | B18: 4. Infraestrutura urbana e mobilidade | C18: Infraestrutura crítica | D18: SIG | E18: Aumenta | F18: Que serviços essenciais param? | G18: Nº de tipos distintos no círculo: energia, telecom, transporte, saneamento. | H18: 0 tipos | I18: 1 tipo | J18: 2 tipos | K18: 3 tipos | L18: ≥4 tipos | M18: Cadastros das concessionárias e da Prefeitura. | O18: Concessionárias (energia, telecom); Compesa; Defesa Civil | P18: Sem cadastro georreferenciado, a Defesa Civil pode indicar de forma qualitativa. | Q18: A verificar
A19: 15 | B19: 4. Infraestrutura urbana e mobilidade | C19: Equipamentos de emergência expostos | D19: SIG | E19: Aumenta | F19: Há equipamento de emergência no local? | G19: Equipamento de saúde ou emergência dentro do círculo. | H19: Nenhum | I19: — | J19: UBS/USF | K19: — | L19: Hospital, UPA, bombeiros ou Defesa Civil | M19: CNES/DATASUS e cadastro da Prefeitura. | O19: CNES (público); Prefeitura | P19: CNES não verificado nesta pesquisa. | Q19: A verificar
A20: 16 | B20: 4. Infraestrutura urbana e mobilidade | C20: Acessibilidade de resposta | D20: SIG | E20: Reduz (escala já invertida) | F20: A resposta consegue chegar rápido? | G20: Tempo de deslocamento ao equipamento de emergência mais próximo pela malha viária (análise de rede). | H20: ≤5 min | I20: 5–10 min | J20: 10–15 min | K20: 15–20 min | L20: >20 min | M20: Malha viária + localização de equipamentos de emergência. | O20: Prefeitura; CNES | P20: Nota 5 = resposta mais difícil. Faixas provisórias. | Q20: A verificar
A21: 17 | B21: 5. Ambiental e sanitário | C21: Área ambientalmente sensível | D21: SIG | E21: Aumenta | F21: Há ambiente sensível afetado? | G21: % do círculo ocupado por APP, margem de rio ou mangue. | H21: 0% | I21: <5% | J21: 5–15% | K21: 15–30% | L21: >30% | M21: Camadas ambientais da Prefeitura; MapBiomas. | N21: Abrir | O21: Prefeitura (meio ambiente) | P21: Faixas provisórias. | Q21: A verificar
A22: 18 | B22: 5. Ambiental e sanitário | C22: Infraestrutura verde (inverso) | D22: SIG | E22: Reduz (escala já invertida) | F22: Há verde ou solo permeável que alivia o escoamento? | G22: % do círculo com vegetação ou solo permeável. | H22: >40% | I22: 30–40% | J22: 20–30% | K22: 10–20% | L22: <10% | M22: MapBiomas; camadas da Prefeitura. | O22: MapBiomas (público); Prefeitura | P22: Nota 5 = pouco verde. Fonte MapBiomas não verificada. | Q22: A verificar
A23: 19 | B23: 5. Ambiental e sanitário | C23: Risco sanitário | D23: Ponto | E23: Aumenta | F23: O alagamento vem misturado com esgoto? | G23: Classificação por vistoria e dados da concessionária. | H23: Sem rede mista nem relatos | I23: — | J23: Ligações irregulares ou relatos | K23: — | L23: Rede unitária, esgoto a céu aberto ou extravasamento visível | M23: Compesa (rede de esgoto), EMLURB e campo. | O23: Compesa; EMLURB; campo | P23: Reflete o ponto de saúde pública: leptospirose e contaminação. | Q23: A verificar
A24: 20 | B24: 6. Técnico (sistema de drenagem) | C24: Fragilidade do sistema de drenagem | D24: Ponto | E24: Aumenta | F24: O sistema de drenagem do ponto é frágil? | G24: Checklist de vistoria (cada item 0/1): subdimensionamento, assoreamento ou lixo, última limpeza há mais de 12 meses, estrutura danificada. Nota = 1 + nº de itens. | H24: 0 itens | I24: 1 item | J24: 2 itens | K24: 3 itens | L24: 4 itens | M24: Vistoria técnica no ponto. | O24: EMLURB; URB (a definir quem faz a vistoria) | P24: Em SP, 'vulnerabilidade técnica' avalia a obra; aqui é adaptação para o ponto. | Q24: A verificar
A25: 21 | B25: 6. Técnico (sistema de drenagem) | C25: Dependência de equipamento | D25: Ponto | E25: Aumenta | F25: O ponto depende de bomba, comporta ou válvula? | G25: Classificação por vistoria e cadastro. | H25: Nenhum equipamento | I25: — | J25: Equipamento com redundância | K25: — | L25: Ponto único de falha | M25: Cadastro e vistoria. | O25: EMLURB; URB | Q25: A verificar
A26: 22 | B26: 6. Técnico (sistema de drenagem) | C26: Posição na bacia | D26: Ponto | E26: Aumenta | F26: O ponto está a jusante e recebe água de vários trechos? | G26: Localizar o ponto na hierarquia Bacia → Sub-bacia (Art. 9º do PMDR) e na rede hidrográfica. | H26: Cabeceira / problema local | I26: — | J26: Trecho intermediário | K26: — | L26: Baixada que recebe várias sub-bacias | M26: PMDR e shapefile da rede hidrográfica já exportado do ArcGIS Pro (15 feições). | O26: Prefeitura (PMDR); arquivo próprio | P26: Conferir quais sub-bacias compõem a RPA 6. | Q26: A verificar
A27: 23 | B27: 7. Político e institucional | C27: Repercussão pública | D27: Ponto | E27: Aumenta | F27: O ponto tem visibilidade pública? | G27: Reclamações no 156/ano + notícias + recorrência; nota atribuída pelo grupo (como SP: 'relevância segundo a opinião pública'). | H27: Irrelevante | I27: Pouco relevante | J27: Relevante | K27: Muito relevante | L27: Extremamente relevante | M27: Base do 156; clipping de notícias; avaliação do grupo. | O27: Prefeitura (156); grupo | P27: Peso baixo (SP: 3%). Mostrar ranking com e sem este critério. | Q27: A verificar
A28: 24 | B28: 7. Político e institucional | C28: Pressão institucional | D28: Ponto | E28: Aumenta | F28: Quem cobra solução para o ponto? | G28: Classificação do demandante mais alto. | H28: Sem demanda formal | I28: — | J28: Vereador ou associação | K28: — | L28: MP, gabinete ou imprensa recorrente | M28: Registros de demandas do COP/gabinete; clipping. | O28: COP; gabinete; grupo | P28: Critério mais sujeito a viés. Documentar a justificativa da nota. | Q28: A verificar
A29: 25 | B29: 8. Tratabilidade (fora do score) | C29: Prazo e complexidade de intervir | D29: Tratabilidade | E29: Escala: 5 = mais fácil de intervir | F29: Dá para agir rápido no ponto? | G29: Prazo estimado de execução da intervenção (escala de SP). | H29: 48–60 meses | I29: 36–48 meses | J29: 24–36 meses | K29: 12–24 meses | L29: 0–12 meses | M29: URB / EMLURB. | O29: URB; EMLURB | P29: Fora do score de criticidade. Cruza com a criticidade na matriz de ação. | Q29: A verificar | R29: n/a
A30: 26 | B30: 8. Tratabilidade (fora do score) | C30: Transtornos ao intervir | D30: Tratabilidade | E30: Escala: 5 = mais fácil | F30: A intervenção interdita via importante? | G30: Classe viária interditada durante a intervenção (escala de SP). | H30: Via de trânsito rápido | I30: Via arterial | J30: Via coletora | K30: Via de pedestres | L30: Via local / nenhuma | M30: Classificação viária da CTTU. | O30: CTTU | Q30: A verificar | R30: n/a
A31: 27 | B31: 8. Tratabilidade (fora do score) | C31: Desapropriação | D31: Tratabilidade | E31: Escala: 5 = mais fácil | F31: A intervenção exige desapropriar? | G31: Custo de desapropriação / custo total da intervenção (escala de SP). | H31: >20% | I31: 10–20% | J31: 5–10% | K31: 1–5% | L31: 0–1% | M31: URB; planilha de custos. | O31: URB | Q31: A verificar | R31: n/a
A32: 28 | B32: 8. Tratabilidade (fora do score) | C32: Licenciamento ambiental | D32: Tratabilidade | E32: Escala: 5 = mais fácil | F32: O licenciamento é complexo? | G32: Complexidade (baixa, média, alta). | H32: Alta | I32: — | J32: Média | K32: — | L32: Baixa | M32: Órgão ambiental municipal/estadual. | O32: Órgão ambiental | Q32: A verificar | R32: n/a
A33: 29 | B33: 8. Tratabilidade (fora do score) | C33: Custo de intervenção | D33: Tratabilidade | E33: Escala: 5 = mais barato | F33: Quanto custa resolver? | G33: Estimativa de custo da intervenção no ponto (quintis dos pontos da RPA 6). | H33: Quintil mais caro | I33: Quintil 2 | J33: Quintil 3 | K33: Quintil 4 | L33: Quintil mais barato | M33: URB / EMLURB. | O33: URB; EMLURB | Q33: A verificar | R33: n/a
A34: 30 | B34: 8. Tratabilidade (fora do score) | C34: Governança do ponto | D34: Tratabilidade | E34: Escala: 5 = mais fácil | F34: Existe dono e protocolo para o ponto? | G34: Classificação por levantamento institucional. | H34: Sem dono ou conflito de competência | I34: — | J34: Dono definido, sem protocolo | K34: — | L34: Dono e protocolo definidos | M34: Escuta com o COP e os órgãos. | O34: COP; órgãos | P34: Ligado às 5 perguntas para o COP (nota de Discussão). | Q34: A verificar | R34: n/a
A35: 31 | B35: 8. Tratabilidade (fora do score) | C35: Janela de oportunidade | D35: Tratabilidade | E35: Escala: 5 = mais fácil | F35: Há obra ou orçamento em andamento perto do ponto? | G35: Classificação por levantamento. | H35: Nenhum projeto ou obra próxima | I35: — | J35: Projeto previsto | K35: — | L35: Obra ou orçamento em andamento | M35: URB; planejamento da Prefeitura. | O35: URB; planejamento | Q35: A verificar | R35: n/a
Q37: Soma dos pesos | R37: =SUM(R5:R28)
Q38: Checagem | R38: =IF(R37=0,"Pesos ainda não definidos",IF(ROUND(R37,4)=1,"OK: soma 100%","Ajustar: soma diferente de 100%"))
B40: Soma dos pesos por dimensão (para comparar com SP: Danos evitados 21,7% · Social 20,5% · Econômico 17,5% · Ambiental 15,5% · Construtivo 11,9% · Técnico 6,0% · Infraestrutura 3,9% · Repercussão 3,0%)
B41: 1. Hidrológico | C41: =SUMIF($B$5:$B$28,B41,$R$5:$R$28)
B42: 2. Social | C42: =SUMIF($B$5:$B$28,B42,$R$5:$R$28)
B43: 3. Econômico | C43: =SUMIF($B$5:$B$28,B43,$R$5:$R$28)
...

Sheet Fontes de dados
A1: Inventário de fontes de dados
A2: Verificação: 'Confirmado na busca' = o site/base existe (conteúdo não aberto na íntegra). 'Não verificado' = conhecimento geral, conferir.
A4: Nº | B4: Fonte | C4: Órgão | D4: Dado que fornece | E4: Subcritérios atendidos | F4: Link | G4: Como obter | H4: Verificação | I4: Status | J4: Responsável | K4: Observações
A5: 1 | B5: Censo 2022: agregados por setor censitário | C5: IBGE | D5: População e domicílios por setor | E5: População exposta; Grupos sensíveis | F5: Abrir | G5: Download público do arquivo de agregados (Pernambuco). | H5: Confirmado na busca | I5: A verificar | K5: Juntar com a malha de setores para o cálculo no círculo.
A6: 2 | B6: Malha de setores censitários 2022 | C6: IBGE | D6: Polígonos dos setores (shapefile/geopackage) | E6: População exposta; Grupos sensíveis | F6: Abrir | G6: Geociências → Estrutura Territorial → Malha de Setores Censitários. | H6: Confirmado na busca | I6: A verificar | K6: Formato shapefile, geopackage ou KML.
A7: 3 | B7: Portal de Dados Abertos da Prefeitura do Recife | C7: Prefeitura do Recife | D7: 222 conjuntos (saúde, CTTU, meio ambiente, empresas, infraestrutura urbana) | E7: Comércios; Edificações; Vias; Área sensível; Equipamentos | F7: Abrir | G7: Menu 'Conjunto de dados'. Buscar: drenagem, alagamento, canal, 156, pluviômetro, empresas, vias. | H7: Confirmado na busca | I7: A verificar | K7: Não foi verificado se há camada de alagamento ou drenagem.
A8: 4 | B8: Hub de Dados Abertos da Prefeitura do Recife | C8: Prefeitura do Recife | D8: Camadas geográficas | E8: Vários subcritérios [SIG] | F8: Abrir | G8: Navegar o catálogo de camadas; baixar as que cobrem a RPA 6. | H8: Confirmado na busca | I8: A verificar | K8: Conferir formatos disponíveis.
A9: 5 | B9: Mapa interativo de pluviômetros automáticos | C9: Cemaden | D9: Chuva por pluviômetro; histórico desde 2013 | E9: Gatilho de chuva; Frequência | F9: Abrir | G9: Botão 'Download de Dados', escolher o equipamento e preencher formulário; o link chega por e-mail. Mês a mês. | H9: Confirmado na busca | I9: A verificar | K9: Sedec usa 8 pluviômetros do Cemaden no Recife (ex.: Imbiribeira).
A10: 6 | B10: Meteorologia / monitoramento de chuvas | C10: APAC | D10: Chuva por pluviômetro, banco estadual de precipitação | E10: Gatilho de chuva; Influência da maré | F10: Abrir | G10: Consultar por período, pluviômetro e mesorregião. | H10: Confirmado na busca | I10: A verificar | K10: Rede estadual de 352 pluviômetros.
A11: 7 | B11: Índice de Vulnerabilidade Social (IVS) | C11: Ipea | D11: IVS por UDH (infraestrutura urbana, capital humano, renda e trabalho) | E11: Vulnerabilidade social | F11: Abrir | G11: Mapa e download no site do Ipea; Atlas do Desenvolvimento Humano. | H11: Confirmado na busca | I11: A verificar | K11: Anos 2000 e 2010; granularidade UDH.
A12: 8 | B12: Registro de ocorrências de alagamento | C12: COP / Defesa Civil (Sedec) | D12: Ocorrências por local e data | E12: Frequência; Gatilho; Altura da lâmina; Duração; Pressão institucional | G12: Solicitar à COP e à Defesa Civil, preferencialmente via tutora/CGM. | H12: Não verificado | I12: A verificar | K12: É a fonte mais crítica. Perguntar formato e série histórica.
A13: 9 | B13: Base de reclamações do 156 | C13: Prefeitura do Recife | D13: Reclamações por tipo e endereço | E13: Repercussão; Frequência (complemento) | G13: Verificar se há base aberta; senão, solicitar extração por categoria (alagamento, drenagem, obstrução). | H13: Não verificado | I13: A verificar
A14: 10 | B14: Registros de serviço e vistoria | C14: EMLURB | D14: Limpeza de canais, manutenção, vistoria de drenagem | E14: Custo recorrente; Fragilidade; Dependência de equipamento | G14: Solicitar à EMLURB; combinar vistoria com checklist. | H14: Não verificado | I14: A verificar | K14: Definir quem faz a vistoria.
A15: 11 | B15: Projetos e obras de drenagem | C15: URB | D15: Obras em andamento e previstas, custos | E15: Tratabilidade (prazo, custo, desapropriação, janela de oportunidade) | G15: Solicitar à URB; também consultar o sistema Target, se aplicável. | H15: Não verificado | I15: A verificar
A16: 12 | B16: Rede de esgoto e extravasamentos | C16: Compesa | D16: Rede de esgoto, ocorrências | E16: Risco sanitário; Infraestrutura crítica | G16: Solicitar à Compesa. | H16: Não verificado | I16: A verificar
A17: 13 | B17: Cadastro de infraestrutura crítica | C17: Concessionárias de energia e telecom; Prefeitura | D17: Subestações, torres, redes | E17: Infraestrutura crítica | G17: Solicitar; alternativa: levantamento qualitativo com a Defesa Civil. | H17: Não verificado | I17: A verificar
A18: 14 | B18: CNES / DATASUS | C18: Ministério da Saúde | D18: Estabelecimentos de saúde georreferenciáveis | E18: Equipamentos de emergência; Acessibilidade de resposta | G18: Download do cadastro de estabelecimentos de Recife e geocodificação. | H18: Não verificado | I18: A verificar
A19: 15 | B19: OpenStreetMap | C19: Comunidade OSM | D19: Vias, comércios, equipamentos | E19: Vias; Comércios; Equipamentos | G19: Download por extração regional (por exemplo, Geofabrik) ou Overpass. | H19: Não verificado | I19: A verificar | K19: Qualidade varia por bairro.
A20: 16 | B20: MapBiomas | C20: MapBiomas | D20: Cobertura e uso do solo | E20: Infraestrutura verde; Área sensível | G20: Download da coleção para a área de Recife. | H20: Não verificado | I20: A verificar
A21: 17 | B21: Tábua de marés | C21: Marinha do Brasil / Porto do Recife | D21: Previsão de marés | E21: Influência da maré | G21: Consultar tábua do porto de Recife. | H21: Não verificado | I21: A verificar
A22: 18 | B22: Linhas e itinerários de ônibus | C22: CTTU / Grande Recife Consórcio | D22: Itinerários e frequência | E22: Vias e mobilidade afetadas | G22: Verificar dados abertos do transporte. | H22: Não verificado | I22: A verificar
A23: 19 | B23: PMDR: Plano Municipal de Drenagem | C23: Prefeitura do Recife | D23: Bacias, sub-bacias, diretrizes | E23: Posição na bacia | G23: Art. 9º já transcrito no vault; conferir quais sub-bacias compõem a RPA 6. | H23: Não verificado | I23: A verificar | K23: Hierarquia: Bacia → Sub-bacia → Ponto Crítico → Obra.
A24: 20 | B24: Shapefile da rede hidrográfica | C24: Arquivo próprio (ArcGIS Pro) | D24: 15 feições de rios e riachos de Recife | E24: Posição na bacia | G24: Arquivo exportado pelo próprio Pedro (exportação_rio_riacho.shp), na Área de Trabalho/vault. | H24: Não verificado | I24: A verificar | K24: Projeção GCS WGS 1984; reprojetar para EPSG:31985.
A25: 21 | B25: Escuta de campo | C25: Moradores e equipes de campo | D25: Altura da lâmina, duração, maré, percepção | E25: Altura da lâmina; Duração; Influência da maré; Grupos sensíveis | G25: Roteiro de escuta com moradores e equipe EMLURB/Defesa Civil. | H25: Não verificado | I25: A verificar | K25: Registrar em faixas (tornozelo, joelho, cintura).
A26: 22 | B26: Clipping de notícias | C26: Mídia | D26: Matérias sobre alagamento por local | E26: Repercussão; Pressão institucional | G26: Busca sistemática por nome do ponto/bairro. | H26: Não verificado | I26: A verificar

Sheet Pontos RPA 6
A1: Pontos críticos da RPA 6 — notas por subcritério e score de criticidade
A2: Pontos da planilha da EMLURB para a RPA 6 (21 trechos). Coordenadas geocodificadas automaticamente (OSM): 'Aproximado' = precisa conferir no mapa. Bacia e sub-bacia a preencher. Notas de 1 a 5 conforme aba Critérios; pesos vêm da aba Critérios. Notas em branco são ignoradas.
G4: Hidrológico | H4: Hidrológico | I4: Hidrológico | J4: Hidrológico | K4: Hidrológico | L4: Hidrológico | M4: Social | N4: Social | O4: Social | P4: Econômico | Q4: Econômico | R4: Econômico | S4: Infraestrutura urbana e mobilidade | T4: Infraestrutura urbana e mobilidade | U4: Infraestrutura urbana e mobilidade | V4: Infraestrutura urbana e mobilidade | W4: Ambiental e sanitário | X4: Ambiental e sanitário | Y4: Ambiental e sanitário | Z4: Técnico (sistema de drenagem) | AA4: Técnico (sistema de drenagem) | AB4: Técnico (sistema de drenagem) | AC4: Político e institucional | AD4: Político e institucional
F5: Peso → | G5: =Critérios!R5 | H5: =Critérios!R6 | I5: =Critérios!R7 | J5: =Critérios!R8 | K5: =Critérios!R9 | L5: =Critérios!R10 | M5: =Critérios!R11 | N5: =Critérios!R12 | O5: =Critérios!R13 | P5: =Critérios!R14 | Q5: =Critérios!R15 | R5: =Critérios!R16 | S5: =Critérios!R17 | T5: =Critérios!R18 | U5: =Critérios!R19 | V5: =Critérios!R20 | W5: =Critérios!R21 | X5: =Critérios!R22 | Y5: =Critérios!R23 | Z5: =Critérios!R24 | AA5: =Critérios!R25 | AB5: =Critérios!R26 | AC5: =Critérios!R27 | AD5: =Critérios!R28
A6: ID | B6: Ponto crítico / local | C6: Bacia | D6: Sub-bacia | E6: Latitude | F6: Longitude | G6: Frequência de eventos [Ponto] | H6: Gatilho de chuva [Ponto] | I6: Influência da maré [Ponto] | J6: Altura da lâmina d'água [Ponto] | K6: Extensão da mancha [Ponto] | L6: Duração do alagamento [Ponto] | M6: População exposta [SIG] | N6: Vulnerabilidade social [SIG] | O6: Grupos sensíveis [SIG] | P6: Comércios no entorno [SIG] | Q6: Importância das edificações [SIG] | R6: Custo recorrente de conviver com o ponto [Ponto] | S6: Vias e mobilidade afetadas [SIG] | T6: Infraestrutura crítica [SIG] | U6: Equipamentos de emergência expostos [SIG] | V6: Acessibilidade de resposta [SIG] | W6: Área ambientalmente sensível [SIG] | X6: Infraestrutura verde (inverso) [SIG] | Y6: Risco sanitário [Ponto] | Z6: Fragilidade do sistema de drenagem [Ponto] | AA6: Dependência de equipamento [Ponto] | AB6: Posição na bacia [Ponto] | AC6: Repercussão pública [Ponto] | AD6: Pressão institucional [Ponto] | AE6: Score de criticidade (1–5) | AF6: Posição | AG6: Tipo (ponto/linha) [EMLURB] | AH6: Precisão da coordenada | AI6: Prioridade EMLURB
A7: 5 | B7: Boa Viagem — Avenida Conselheiro Aguiar (Interseção com a Rua Tenente João Cícero) | E7: -8.113732 | F7: -34.893163 | AE7: =IF(SUM($G$5:$AD$5)=0,"",IFERROR(SUMPRODUCT(G7:AD7,$G$5:$AD$5)/SUMPRODUCT((G7:AD7<>"")*$G$5:$AD$5),"")) | AF7: =IF(AE7="","",RANK(AE7,$AE$7:$AE$36)) | AG7: Ponto | AH7: Interseção | AI7: Não
A8: 6 | B8: Boa Viagem — Avenida Conselheiro Aguiar (Interseção com a Rua Dona Benvinda) | E8: -8.111009 | F8: -34.891491 | AE8: =IF(SUM($G$5:$AD$5)=0,"",IFERROR(SUMPRODUCT(G8:AD8,$G$5:$AD$5)/SUMPRODUCT((G8:AD8<>"")*$G$5:$AD$5),"")) | AF8: =IF(AE8="","",RANK(AE8,$AE$7:$AE$36)) | AG8: Ponto | AH8: Interseção | AI8: Não
A9: 7 | B9: Boa Viagem — Avenida Conselheiro Aguiar (Interseção com a Rua Maria Carolina) | E9: -8.11538 | F9: -34.894176 | AE9: =IF(SUM($G$5:$AD$5)=0,"",IFERROR(SUMPRODUCT(G9:AD9,$G$5:$AD$5)/SUMPRODUCT((G9:AD9<>"")*$G$5:$AD$5),"")) | AF9: =IF(AE9="","",RANK(AE9,$AE$7:$AE$36)) | AG9: Ponto | AH9: Interseção | AI9: Não
A10: 8 | B10: Boa Viagem — Avenida Conselheiro Aguiar (Do nº 1501 até a Rua Baltazar Pereira) | E10: -8.101066 | F10: -34.886765 | AE10: =IF(SUM($G$5:$AD$5)=0,"",IFERROR(SUMPRODUCT(G10:AD10,$G$5:$AD$5)/SUMPRODUCT((G10:AD10<>"")*$G$5:$AD$5),"")) | AF10: =IF(AE10="","",RANK(AE10,$AE$7:$AE$36)) | AG10: Linha | AH10: Interseção | AI10: Não
A11: 9 | B11: Imbiribeira — Avenida Mascarenhas de Moraes (Da Rua General Mac Arthur até a Universo) | E11: -8.108934 | F11: -34.911777 | AE11: =IF(SUM($G$5:$AD$5)=0,"",IFERROR(SUMPRODUCT(G11:AD11,$G$5:$AD$5)/SUMPRODUCT((G11:AD11<>"")*$G$5:$AD$5),"")) | AF11: =IF(AE11="","",RANK(AE11,$AE$7:$AE$36)) | AG11: Linha | AH11: Interseção | AI11: Não
A12: 11 | B12: Boa Viagem — Rua Professor José Brandão (Toda a extensão) | E12: -8.111816 | F12: -34.894789 | AE12: =IF(SUM($G$5:$AD$5)=0,"",IFERROR(SUMPRODUCT(G12:AD12,$G$5:$AD$5)/SUMPRODUCT((G12:AD12<>"")*$G$5:$AD$5),"")) | AF12: =IF(AE12="","",RANK(AE12,$AE$7:$AE$36)) | AG12: Linha | AH12: Aproximado | AI12: Não
A13: 12 | B13: Boa Viagem — Rua Padre Bernardino Pessoa (Da Avenida Conselheiro Aguiar até a Via Mangue) | E13: -8.112935 | F13: -34.896796 | AE13: =IF(SUM($G$5:$AD$5)=0,"",IFERROR(SUMPRODUCT(G13:AD13,$G$5:$AD$5)/SUMPRODUCT((G13:AD13<>"")*$G$5:$AD$5),"")) | AF13: =IF(AE13="","",RANK(AE13,$AE$7:$AE$36)) | AG13: Linha | AH13: Aproximado | AI13: Não
A14: 18 | B14: Boa Viagem — Rua Jornalista Alfredo Porto Silveira (Toda a extensão) | E14: -8.138796 | F14: -34.913979 | AE14: =IF(SUM($G$5:$AD$5)=0,"",IFERROR(SUMPRODUCT(G14:AD14,$G$5:$AD$5)/SUMPRODUCT((G14:AD14<>"")*$G$5:$AD$5),"")) | AF14: =IF(AE14="","",RANK(AE14,$AE$7:$AE$36)) | AG14: Linha | AH14: Aproximado | AI14: Não
A15: 19 | B15: Pina — Rua São Luiz (Final da rua) | E15: -8.089716 | F15: -34.888275 | AE15: =IF(SUM($G$5:$AD$5)=0,"",IFERROR(SUMPRODUCT(G15:AD15,$G$5:$AD$5)/SUMPRODUCT((G15:AD15<>"")*$G$5:$AD$5),"")) | AF15: =IF(AE15="","",RANK(AE15,$AE$7:$AE$36)) | AG15: Ponto | AH15: Aproximado | AI15: Não
A16: 22 | B16: Jordão — Avenida Maria Irene (Vários trechos) | E16: -8.140505 | F16: -34.927358 | AE16: =IF(SUM($G$5:$AD$5)=0,"",IFERROR(SUMPRODUCT(G16:AD16,$G$5:$AD$5)/SUMPRODUCT((G16:AD16<>"")*$G$5:$AD$5),"")) | AF16: =IF(AE16="","",RANK(AE16,$AE$7:$AE$36)) | AG16: Vários | AH16: Aproximado | AI16: Não
A17: 24 | B17: Ipsep — Rua Blumenau (Até a maré) | E17: -8.107611 | F17: -34.920256 | AE17: =IF(SUM($G$5:$AD$5)=0,"",IFERROR(SUMPRODUCT(G17:AD17,$G$5:$AD$5)/SUMPRODUCT((G17:AD17<>"")*$G$5:$AD$5),"")) | AF17: =IF(AE17="","",RANK(AE17,$AE$7:$AE$36)) | AG17: Linha | AH17: Aproximado | AI17: Sim
A18: 25 | B18: Ipsep — Rua Raimundo Diniz (Vários trechos) | E18: -8.114288 | F18: -34.921465 | AE18: =IF(SUM($G$5:$AD$5)=0,"",IFERROR(SUMPRODUCT(G18:AD18,$G$5:$AD$5)/SUMPRODUCT((G18:AD18<>"")*$G$5:$AD$5),"")) | AF18: =IF(AE18="","",RANK(AE18,$AE$7:$AE$36)) | AG18: Vários | AH18: Aproximado | AI18: Não
... A27: 54 | B27: Ibura — Rua Rio Prado (Interseção da Rua Rio Prado com a Rua Rio Brígida) | E27: -8.113869 | F27: -34.940702 | AE27: =IF(SUM($G$5:$AD$5)=0,"",IFERROR(SUMPRODUCT(G27:AD27,$G$5:$AD$5)/SUMPRODUCT((G27:AD27<>"")*$G$5:$AD$5),"")) | AF27: =IF(AE27="","",RANK(AE27,$AE$7:$AE$36)) | AG27: Ponto | AH27: Interseção | AI27: Não
AE28: =IF(SUM($G$5:$AD$5)=0,"",IFERROR(SUMPRODUCT(G28:AD28,$G$5:$AD$5)/SUMPRODUCT((G28:AD28<>"")*$G$5:$AD$5),"")) | AF28: =IF(AE28="","",RANK(AE28,$AE$7:$AE$36))
AE29: =IF(SUM($G$5:$AD$5)=0,"",IFERROR(SUMPRODUCT(G29:AD29,$G$5:$AD$5)/SUMPRODUCT((G29:AD29<>"")*$G$5:$AD$5),"")) | AF29: =IF(AE29="","",RANK(AE29,$AE$7:$AE$36))
AE30: =IF(SUM($G$5:$AD$5)=0,"",IFERROR(SUMPRODUCT(G30:AD30,$G$5:$AD$5)/SUMPRODUCT((G30:AD30<>"")*$G$5:$AD$5),"")) | AF30: =IF(AE30="","",RANK(AE30,$AE$7:$AE$36))
AE31: =IF(SUM($G$5:$AD$5)=0,"",IFERROR(SUMPRODUCT(G31:AD31,$G$5:$AD$5)/SUMPRODUCT((G31:AD31<>"")*$G$5:$AD$5),"")) | AF31: =IF(AE31="","",RANK(AE31,$AE$7:$AE$36))
AE32: =IF(SUM($G$5:$AD$5)=0,"",IFERROR(SUMPRODUCT(G32:AD32,$G$5:$AD$5)/SUMPRODUCT((G32:AD32<>"")*$G$5:$AD$5),"")) | AF32: =IF(AE32="","",RANK(AE32,$AE$7:$AE$36))
AE33: =IF(SUM($G$5:$AD$5)=0,"",IFERROR(SUMPRODUCT(G33:AD33,$G$5:$AD$5)/SUMPRODUCT((G33:AD33<>"")*$G$5:$AD$5),"")) | AF33: =IF(AE33="","",RANK(AE33,$AE$7:$AE$36))
AE34: =IF(SUM($G$5:$AD$5)=0,"",IFERROR(SUMPRODUCT(G34:AD34,$G$5:$AD$5)/SUMPRODUCT((G34:AD34<>"")*$G$5:$AD$5),"")) | AF34: =IF(AE34="","",RANK(AE34,$AE$7:$AE$36))
AE35: =IF(SUM($G$5:$AD$5)=0,"",IFERROR(SUMPRODUCT(G35:AD35,$G$5:$AD$5)/SUMPRODUCT((G35:AD35<>"")*$G$5:$AD$5),"")) | AF35: =IF(AE35="","",RANK(AE35,$AE$7:$AE$36))
AE36: =IF(SUM($G$5:$AD$5)=0,"",IFERROR(SUMPRODUCT(G36:AD36,$G$5:$AD$5)/SUMPRODUCT((G36:AD36<>"")*$G$5:$AD$5),"")) | AF36: =IF(AE36="","",RANK(AE36,$AE$7:$AE$36))
